Workbook

Sheet Identifier
A1: 0
A2: EOEG Overall Norms Particulars | B2: Cost Category | C2: Standard Code | D2: Code as per MIIS / Contribution Report | E2: Column3 | F2: JMDC2 | G2: JMDC3 | H2: DMD | I2: Column1 | J2: HMD1 | K2: HMD12 | L2: HMD2 | M2: HMD22 | N2: HMD3 | O2: HMD4 | P2: NMD | Q2: Column2 | R2: VMD | S2: Plants
B3: Production | C3: EOE | D3: ETHYLENE OXIDE EQUIVALENT | F3: 1 | H3: 1 | J3: 1 | L3: 1 | N3: 1 | P3: 1 | R3: 1 | S3: =SUM(Identifier!$F3:$R3) -> 7
C4: Operating Hrs | F4: 1 | H4: 1 | J4: 1 | L4: 1 | N4: 1 | P4: 1 | R4: 1 | S4: =SUM(Identifier!$F4:$R4) -> 7
B5: Product | C5: PEO | D5: ETHYLENE OXIDE | F5: 0 | H5: 1 | J5: 1 | L5: 1 | N5: 1 | P5: 1 | R5: 1 | S5: =SUM(Identifier!$F5:$R5) -> 6
B6: Product | C6: MEG | D6: MONO ETHYLENE GLYCOL | F6: 1 | H6: 1 | J6: 1 | L6: 1 | N6: 1 | P6: 1 | R6: 1 | S6: =SUM(Identifier!$F6:$R6) -> 7
B7: By Product | C7: DEG | D7: DI ETHYLENE GLYCOL | F7: 1 | H7: 1 | J7: 1 | L7: 1 | N7: 1 | P7: 0 | R7: 0 | S7: =SUM(Identifier!$F7:$R7) -> 5
B8: By Product | C8: TEG | D8: TRI ETHYLENEGLYCOL B | F8: 0 | H8: 1 | J8: 1 | L8: 1 | N8: 1 | P8: 0 | R8: 0 | S8: =SUM(Identifier!$F8:$R8) -> 4
B9: By Product | C9: PEG | D9: Glycol Residue WIP | F9: 1 | H9: 0 | J9: 0 | L9: 0 | N9: 0 | P9: 0 | R9: 0 | S9: =SUM(Identifier!$F9:$R9) -> 1
B10: By Product | C10: PEG | D10: TEG-BOTTOM | F10: 0 | H10: 1 | J10: 0 | L10: 0 | N10: 0 | P10: 0 | R10: 0 | S10: =SUM(Identifier!$F10:$R10) -> 1
B11: By Product | C11: PEG | D11: POLY ETHYLENE GLYCOL | F11: 0 | H11: 0 | J11: 0 | L11: 0 | N11: 0 | P11: 1 | R11: 1 | S11: =SUM(Identifier!$F11:$R11) -> 2
B12: By Product | C12: GR-1 | D12: GLYCOL RESIDUE I | F12: 0 | H12: 0 | J12: 1 | L12: 1 | N12: 1 | P12: 0 | R12: 0 | S12: =SUM(Identifier!$F12:$R12) -> 3
B13: By Product | C13: GR-2 | D13: GLYCOL RESIDUE II | F13: 0 | H13: 0 | J13: 1 | L13: 1 | N13: 1 | P13: 0 | R13: 0 | S13: =SUM(Identifier!$F13:$R13) -> 3
B14: By Product | C14: CO2 | D14: Carbon Dioxide | F14: 0 | H14: 0 | J14: 1 | L14: 0 | N14: 0 | P14: 1 | R14: 1 | S14: =SUM(Identifier!$F14:$R14) -> 3
B15: By Product | C15: PVG | D15: MIXED PETROLEUM GAS | F15: 1 | H15: 0 | J15: 0 | L15: 0 | N15: 0 | P15: 0 | R15: 0 | S15: =SUM(Identifier!$F15:$R15) -> 1
B16: By Product | C16: PVG | D16: Process Vent Gas | F16: 0 | H16: 0 | J16: 1 | L16: 1 | N16: 1 | P16: 0 | R16: 0 | S16: =SUM(Identifier!$F16:$R16) -> 3
... B81: CatChem | C81: VASUCOR | D81: CORROSION INHIBITOR VASUCOR-NM612 | F81: 1 | H81: 0 | J81: 0 | L81: 0 | N81: 0 | P81: 0 | R81: 0 | S81: =SUM(Identifier!$F81:$R81) -> 1

Sheet DCT Norms Basis
A1: 1
A2: EOEG Overall Norms Setting comparisons - Current | B2: Cost Category | C2: Standard Code | D2: Code as per MIIS / Contribution Report | E2: JMDC2 - UoM | F2: JMDC2 - Norms | G2: DMD - UoM | H2: DMD - Norms | I2: HMD1 - UoM | J2: HMD1 - Norms | K2: HMD2 - UoM | L2: HMD2 - Norms | M2: HMD3 - UoM | N2: HMD3 - Norms | O2: NMD - UoM | P2: NMD - Norms | Q2: VMD - UoM | R2: VMD - Norms | T2: Legend
B3: Production | C3: EOE | D3: ETHYLENE OXIDE EQUIVALENT | E3: TPM | F3: as per Production setting philosophy | G3: TPM | H3: as per Production setting philosophy | I3: TPM | J3: as per Production setting philosophy | K3: TPM | L3: as per Production setting philosophy | M3: TPM | N3: as per Production setting philosophy | O3: TPM | P3: as per Production setting philosophy | Q3: TPM | R3: as per Production setting philosophy | T3: [ XXX ] | U3: Term Within Norms Table
C4: Op hrs | D4: Steady state Operating Hours per month | E4: hrs | F4: as per Shutdown Slowdown Planning | G4: hrs | H4: as per Shutdown Slowdown Planning | I4: hrs | J4: as per Shutdown Slowdown Planning | K4: hrs | L4: as per Shutdown Slowdown Planning | M4: hrs | N4: as per Shutdown Slowdown Planning | O4: hrs | P4: as per Shutdown Slowdown Planning | Q4: hrs | R4: as per Shutdown Slowdown Planning
B5: Product | C5: EO | D5: ETHYLENE OXIDE | G5: TPM | H5: as per Production setting philosophy | I5: TPM | J5: as per Production setting philosophy | K5: TPM | L5: as per Production setting philosophy | M5: TPM | N5: as per Production setting philosophy | O5: TPM | P5: as per Production setting philosophy | Q5: TPM | R5: as per Production setting philosophy | T5: { XXX } | U5: Calculation from "Other Calculations / Inputs" Table
B6: Product | C6: MEG | D6: MONO ETHYLENE GLYCOL | E6: TPM | F6: {MEG Yield}*[EOE] | G6: TPM | H6: {MEG Yield}*([EOE]-[EO]) | I6: TPM | J6: {MEG Yield}*([EOE]-[EO]) | K6: TPM | L6: {MEG Yield}*([EOE]-[EO]) | M6: TPM | N6: {MEG Yield}*([EOE]-[EO]) | O6: TPM | P6: {MEG Yield}*([EOE]-[EO]) | Q6: TPM | R6: {MEG Yield}*([EOE]-[EO]) | T6: XXX | U6: Comment / Remark
B7: By Product | C7: DEG | D7: DI ETHYLENE GLYCOL | E7: MT / MT EOE | F7: 0.1022*[EOE] | G7: MT / MT EOE | H7: 0.101*[MEG]/[EOE] | I7: MT / MT EOE | J7: 0.1141*[MEG]/[EOE] | K7: MT / MT EOE | L7: 0.1141*[MEG]/[EOE] | M7: MT / MT EOE | N7: 0.1141*[MEG]/[EOE]
B8: By Product | C8: TEG | D8: TRI ETHYLENEGLYCOL B | G8: MT / MT EOE | H8: 0.0033*[MEG]/[EOE] | I8: MT / MT EOE | J8: 0.00629*[MEG]/[EOE] | K8: MT / MT EOE | L8: 0.00629*[MEG]/[EOE] | M8: MT / MT EOE | N8: 0.00629*[MEG]/[EOE]
B9: By Product | C9: PEG | D9: Glycol Residue WIP | E9: MT / MT EOE | F9: HISTORIAN - As per AVERAGE achieved norms at resp. throughput
B10: By Product | C10: PEG | D10: TEG-BOTTOM | G10: MT / MT EOE | H10: 0.0030*[MEG]/[EOE]
B11: By Product | C11: PEG | D11: POLY ETHYLENE GLYCOL | O11: MT / MT EOE | P11: 0.08*[MEG]/[EOE] | Q11: MT / MT EOE | R11: (3%)*(105.5/2/44.05)*([EOE]-[EO])/[EOE]
B12: By Product | C12: GR-1 | D12: GLYCOL RESIDUE I | I12: MT / MT EOE | J12: 0.0015 | K12: MT / MT EOE | L12: 0.0015 | M12: MT / MT EOE | N12: 0.0015
B13: By Product | C13: GR-2 | D13: GLYCOL RESIDUE II | I13: MT / MT EOE | J13: 0.0015 | K13: MT / MT EOE | L13: 0.0015 | M13: MT / MT EOE | N13: 0.0015
B14: By Product | C14: CO2 | D14: Carbon Dioxide | I14: NM3 / MT EOE | J14: BUSINESS DEMAND | O14: MT / MT EOE | P14: Min of 1. BUSINESS DEMAND, 2. {CO2 Production} - based on Selectivity | Q14: MT / MT EOE | R14: Min of 1. BUSINESS DEMAND, 2. {CO2 Production} - based on Selectivity
B15: By Product | C15: PVG | D15: MIXED PETROLEUM GAS | E15: MT / MT EOE | F15: HISTORIAN - As per PREVIOUS YEAR achieved norms at resp. throughput
B16: By Product | C16: PVG | D16: Process Vent Gas | I16: MT / MT EOE | J16: [METHANE]/16/0.54*22.4*0.9 | K16: MT / MT EOE | L16: [METHANE]/16/0.54*22.4*0.9 | M16: MT / MT EOE | N16: [METHANE]/16/0.54*22.4*0.9
B17: Raw Material | C17: Ethylene | D17: ETHYLENE | E17: MT / MT EOE | F17: (28.05/44.05*100/{selectivity}/0.9995)+([METHANE]*28.05*0.32/16/0.525))/0.9995) | G17: MT / MT EOE | H17: (28.05/44.05*100/{selectivity}/0.9995)+([METHANE]*28.05*0.28/16/0.54))/0.9995)+((1.9/24)/([EOE]/[Op hrs])) | I17: MT / MT EOE | J17: (((1.001*28*100/44/{selectivity})+([METHANE]*28*0.28/16/0.54))/0.999)+(0.135/24/([EOE]/[Op hrs])) | K17: MT / MT EOE | L17: (((1.001*28*100/44/{selectivity})+([METHANE]*28*0.28/16/0.54))/0.999)+(0.135/24/([EOE]/[Op hrs])) | M17: MT / MT EOE | N17: (((1.001*28*100/44/{selectivity})+([METHANE]*28*0.28/16/0.54))/0.999)+(0.135/24/([EOE]/[Op hrs])) | O17: MT / MT EOE | P17: 28.05/44.05*100/{selectivity}*1.018/0.997 | Q17: MT / MT EOE | R17: (28.05/44.05*100/{selectivity}*1.02/0.998)+(30/21.5*35*28.05/100/([EOE]/[Op hrs]))+({CO2 Production}*0.003/[EOE])+(5/([EOE]/[Op hrs]))
B18: Raw Material | C18: Oxygen | D18: OXYGEN | E18: MT / MT EOE | F18: ((100*2.1818/{selectivity}-1.818)+([METHANE]*32*0.065/16/0.525))/0.998 | G18: MT / MT EOE | H18: (32/44.05*(3/{selectivity}*100-2.5)/0.996)+([METHANE]*32*0.052/16/0.54))/0.996) | O18: MT / MT EOE | P18: 32/44.05*(120-{selectivity})/{selectivity}/40*1.008/0.997 | Q18: MT / MT EOE | R18: (32/44.05*(3/{selectivity}*100-2.5)/0.998)+(30/21.5*5.8*32/100/([EOE]/[Op hrs]))+(4.3/([EOE]/[Op hrs]))
B19: Raw Material | C19: Oxygen | D19: OXYGEN - NP01 | I19: MT / MT EOE | J19: (1.001*(100*2.1818/{selectivity}-1.818)+([METHANE]*32*0.05/16/0.54))/0.997 | K19: MT / MT EOE | L19: (1.001*(100*2.1818/{selectivity}-1.818)+([METHANE]*32*0.05/16/0.54))/0.997 | M19: MT / MT EOE | N19: (1.001*(100*2.1818/{selectivity}-1.818)+([METHANE]*32*0.05/16/0.54))/0.997
B20: Utilities | C20: HHP Steam | D20: SHP STEAM_DIS | E20: MT / MT EOE | F20: {Total HHP Consumption}/([EOE]/[Op hrs])
B21: Utilities | C21: HP Steam | D21: HP STEAM_DIS | G21: MT / MT EOE | H21: * CONDITION: ({Total HP Steam Consumption}-{HP Steam Generation}), * IF (CONDITION > 0): ((Value as per condition)/([EOE]/[Op hrs])) * IF (CONDITION < 0): 0 | I21: MT / MT EOE | J21: * CONDITION: ({Total HP Steam Consumption}-{HP Steam Generation}), * IF (CONDITION > 0): ((Value as per condition)/([EOE]/[Op hrs])) * IF (CONDITION < 0): 0 | K21: MT / MT EOE | L21: * CONDITION: ({Total HP Steam Consumption}-{HP Steam Generation}), * IF (CONDITION > 0): ((Value as per condition)/([EOE]/[Op hrs])) * IF (CONDITION < 0): 0 | M21: MT / MT EOE | N21: * CONDITION: ({Total HP Steam Consumption}-{HP Steam Generation}), * IF (CONDITION > 0): ((Value as per condition)/([EOE]/[Op hrs])) * IF (CONDITION < 0): 0 | O21: MT / MT EOE | P21: {Total HP Consumption}/([EOE]/[Op hrs]) | Q21: MT / MT EOE | R21: ({Total HP Steam Consumption}-{HP Steam Generation})/([EOE]/[Op hrs]))
B22: Utilities | C22: MP Steam | D22: MP STEAM_DIS | E22: MT / MT EOE | F22: {Total MP Consumption}/([EOE]/[Op hrs]) | G22: MT / MT EOE | H22: * CONDITION: ({Total MP Steam Consumption}-{MP Steam Generation}-{Excess HP}), * IF (CONDITION > 0): ((Value as per condition)/([EOE]/[Op hrs])) * IF (CONDITION < 0): 0 | I22: MT / MT EOE | J22: * CONDITION: ({Total MP Steam Consumption}-{MP Steam Generation}-{Excess HP}), * IF (CONDITION > 0): ((Value as per condition)/([EOE]/[Op hrs])) * IF (CONDITION < 0): 0 | K22: MT / MT EOE | L22: * CONDITION: ({Total MP Steam Consumption}-{MP Steam Generation}-{Excess HP}), * IF (CONDITION > 0): ((Value as per condition)/([EOE]/[Op hrs])) * IF (CONDITION < 0): 0 | M22: MT / MT EOE | N22: * CONDITION: ({Total MP Steam Consumption}-{MP Steam Generation}-{Excess HP}), * IF (CONDITION > 0): ((Value as per condition)/([EOE]/[Op hrs])) * IF (CONDITION < 0): 0 | O22: MT / MT EOE | P22: ({Total MP Steam consumption} - {MP Steam Generation})/([EOE]/[Op hrs]) | Q22: MT / MT EOE | R22: {Total MP Steam consumption}/([EOE]/[Op hrs])
B23: Utilities | C23: LP Steam | D23: LP STEAM_DIS | G23: MT / MT EOE | H23: ({Total LP Steam consumption} - {Excess MP})/([EOE]/[Op hrs]) | I23: MT / MT EOE | J23: ({Total LP Steam consumption} - {Excess MP})/([EOE]/[Op hrs]) | K23: MT / MT EOE | L23: ({Total LP Steam consumption} - {Excess MP})/([EOE]/[Op hrs]) | M23: MT / MT EOE | N23: ({Total LP Steam consumption} - {Excess MP})/([EOE]/[Op hrs]) | O23: MT / MT EOE | P23: HISTORIAN - As per PREVIOUS YEAR achieved norms at resp. throughput
B24: Utilities | C24: BFW | D24: BOILER FEED WATER | I24: M3 / MT EOE | J24: ({HP Steam Generation}+0.9+0.9)/([EOE]/[Op hrs]) | K24: M3 / MT EOE | L24: ({HP Steam Generation}+0.9+0.9)/([EOE]/[Op hrs]) | M24: M3 / MT EOE | N24: ({HP Steam Generation}+0.9+0.9)/([EOE]/[Op hrs])
B25: Utilities | C25: Cond. Ret. | D25: RET STEAM CONDENSATE | E25: M3 / MT EOE | F25: ([HPP Steam]+[MP Steam]+[DM Water]-[Effluent])-((40+19)/([EOE]/[Op hrs])) | G25: M3 / MT EOE | H25: ([HP Steam]+[MP Steam]+[LP Steam])*-0.51 | I25: M3 / MT EOE | J25: HISTORIAN - As per PREVIOUS YEAR achieved norms at resp. throughput | K25: M3 / MT EOE | L25: HISTORIAN - As per PREVIOUS YEAR achieved norms at resp. throughput | M25: M3 / MT EOE | N25: HISTORIAN - As per PREVIOUS YEAR achieved norms at resp. throughput | Q25: M3 / MT EOE | R25: HISTORIAN - As per PREVIOUS YEAR achieved norms at resp. throughput
B26: Utilities | C26: Power | D26: POWER_DIS | E26: kWh / MT EOE | F26: HISTORIAN - As per PREVIOUS YEAR achieved norms at resp. throughput | G26: kWh / MT EOE | H26: HISTORIAN - As per PREVIOUS YEAR achieved norms at resp. throughput | I26: kWh / MT EOE | J26: HISTORIAN - As per PREVIOUS YEAR achieved norms at resp. throughput | K26: kWh / MT EOE | L26: HISTORIAN - As per PREVIOUS YEAR achieved norms at resp. throughput | M26: kWh / MT EOE | N26: HISTORIAN - As per PREVIOUS YEAR achieved norms at resp. throughput | O26: kWh / MT EOE | P26: HISTORIAN - As per PREVIOUS YEAR achieved norms at resp. throughput | Q26: kWh / MT EOE | R26: HISTORIAN - As per PREVIOUS YEAR achieved norms at resp. throughput
B27: Utilities | C27: Cooling Water - 1 | D27: Cooling Water | E27: kM3 / MT EOE | F27: HISTORIAN - As per PREVIOUS YEAR achieved norms at resp. throughput
B28: Utilities | C28: Cooling Water - 1 | D28: COOLING WATER D4 | G28: kM3 / MT EOE | H28: HISTORIAN - As per PREVIOUS YEAR achieved norms at resp. throughput
B29: Utilities | C29: Cooling Water - 1 | D29: COOLING WATER_DIS | I29: kM3 / MT EOE | J29: HISTORIAN - As per PREVIOUS YEAR achieved norms at resp. throughput | K29: kM3 / MT EOE | L29: HISTORIAN - As per PREVIOUS YEAR achieved norms at resp. throughput | M29: kM3 / MT EOE | N29: HISTORIAN - As per PREVIOUS YEAR achieved norms at resp. throughput
B30: Utilities | C30: Cooling Water - 1 | D30: COOLING WATER 2 | O30: kM3 / MT EOE | P30: HISTORIAN - As per PREVIOUS YEAR achieved norms at resp. throughput
B31: Utilities | C31: Cooling Water - 1 | D31: N2O2 COOLING WATER | Q31: kM3 / MT EOE | R31: HISTORIAN - As per PREVIOUS YEAR achieved norms at resp. throughput
B32: Utilities | C32: Cooling Water - 2 | D32: COOLING WATER D5 | G32: kM3 / MT EOE | H32: HISTORIAN - As per PREVIOUS YEAR achieved norms at resp. throughput
B33: Utilities | C33: Methane | D33: Methane Ballast | E33: MT / MT EOE | F33: HISTORIAN - As per PREVIOUS YEAR achieved norms at resp. throughput | O33: MT / MT EOE | P33: HISTORIAN - As per PREVIOUS YEAR achieved norms at resp. throughput | Q33: MT / MT EOE | R33: HISTORIAN - As per PREVIOUS YEAR achieved norms at resp. throughput
B34: Utilities | C34: Methane | D34: METHANE | G34: MT / MT EOE | H34: HISTORIAN - As per PREVIOUS YEAR achieved norms at resp. throughput | I34: MT / MT EOE | J34: HISTORIAN - As per PREVIOUS YEAR achieved norms at resp. throughput | K34: MT / MT EOE | L34: HISTORIAN - As per PREVIOUS YEAR achieved norms at resp. throughput | M34: MT / MT EOE | N34: HISTORIAN - As per PREVIOUS YEAR achieved norms at resp. throughput
B35: Utilities | C35: DM Water | D35: D M WATER | E35: M3 / MT EOE | F35: HISTORIAN - As per PREVIOUS YEAR achieved norms at resp. throughput | H35: HISTORIAN - As per PREVIOUS YEAR achieved norms at resp. throughput | I35: M3 / MT EOE | J35: HISTORIAN - As per PREVIOUS YEAR achieved norms at resp. throughput | K35: M3 / MT EOE | L35: HISTORIAN - As per PREVIOUS YEAR achieved norms at resp. throughput | M35: M3 / MT EOE | N35: HISTORIAN - As per PREVIOUS YEAR achieved norms at resp. throughput | O35: M3 / MT EOE | P35: HISTORIAN - As per PREVIOUS YEAR achieved norms at resp. throughput | Q35: M3 / MT EOE | R35: HISTORIAN - As per PREVIOUS YEAR achieved norms at resp. throughput
B36: Utilities | C36: Effluent | D36: EFFLUENT TREATED | E36: M3 / MT EOE | F36: HISTORIAN - As per PREVIOUS YEAR achieved norms at resp. throughput | H36: HISTORIAN - As per PREVIOUS YEAR achieved norms at resp. throughput | I36: M3 / MT EOE | J36: HISTORIAN - As per PREVIOUS YEAR achieved norms at resp. throughput | K36: M3 / MT EOE | L36: HISTORIAN - As per PREVIOUS YEAR achieved norms at resp. throughput | M36: M3 / MT EOE | N36: HISTORIAN - As per PREVIOUS YEAR achieved norms at resp. throughput | Q36: M3 / MT EOE | R36: HISTORIAN - As per PREVIOUS YEAR achieved norms at resp. throughput
B37: Utilities | C37: HP Nitrogen | D37: HP NITROGEN | I37: NM3 / MT EOE | J37: HISTORIAN - As per PREVIOUS YEAR achieved norms at resp. throughput | K37: NM3 / MT EOE | L37: HISTORIAN - As per PREVIOUS YEAR achieved norms at resp. throughput | M37: NM3 / MT EOE | N37: HISTORIAN - As per PREVIOUS YEAR achieved norms at resp. throughput
B38: Utilities | C38: Nitrogen | D38: NITROGEN_ASU | E38: NM3 / MT EOE | F38: HISTORIAN - As per PREVIOUS YEAR achieved norms at resp. throughput
B39: Utilities | C39: Nitrogen | D39: Nitrogen Gas | G39: NM3 / MT EOE | H39: HISTORIAN - As per PREVIOUS YEAR achieved norms at resp. throughput | O39: NM3 / MT EOE | P39: HISTORIAN - As per PREVIOUS YEAR achieved norms at resp. throughput
B40: Utilities | C40: Nitrogen | D40: LP NITROGEN | I40: NM3 / MT EOE | J40: HISTORIAN - As per PREVIOUS YEAR achieved norms at resp. throughput | K40: NM3 / MT EOE | L40: HISTORIAN - As per PREVIOUS YEAR achieved norms at resp. throughput | M40: NM3 / MT EOE | N40: HISTORIAN - As per PREVIOUS YEAR achieved norms at resp. throughput
...
